<?xml version="1.0" ?>
<!-- =================================================================================== -->
<!-- |    This document was autogenerated by xacro from /home/hengchih/hengchih/Robot/Robot_gr_ws/src/handover_robot/robot_description/urdf/mirobot_urdf_2_rg2_gripper_85_gr_fix_joint6.xacro | -->
<!-- |    EDITING THIS FILE BY HAND IS NOT RECOMMENDED                                 | -->
<!-- =================================================================================== -->
<!-- This URDF was automatically created by SolidWorks to URDF Exporter! Originally created by Stephen Brawner (brawner@gmail.com) 
     Commit Version: 1.5.1-0-g916b5db  Build Version: 1.5.7152.31018
     For more information, please see http://wiki.ros.org/sw_urdf_exporter -->
<robot name="robot_description">
    <link name="base_footprint" />
    <link name="base_link">
        <!-- <inertial>
      <mass value="10"/>
      <origin
        xyz="0.00072554 2.2065E-05 0.024268"
        rpy="0 0 0" />
      <mass
        value="0.01" />
      <inertia
        ixx="10"
        ixy="0"
        ixz="0"
        iyy="10"
        iyz="0"
        izz="10" />
    </inertial> -->
        <visual>
            <origin rpy="0 0 0" xyz="0.00072554 2.2065E-05 0.024268" />
            <geometry>
                <mesh filename="package://robot_description/meshes/base_link.STL" />
            </geometry>
            <material name="">
                <color rgba="0.44 0.5 0.56 1" />
            </material>
        </visual>
        <collision>
            <origin rpy="0 0 0" xyz="0 0 0" />
            <geometry>
                <mesh filename="package://robot_description/meshes/base_link.STL" />
            </geometry>
        </collision>
        <inertial>
            <mass value="0.1" />
            <origin xyz="0 0 0" rpy="0 0 0" />
            <inertia ixx="0.03" iyy="0.03" izz="0.03" ixy="0.0" ixz="0.0" iyz="0.0" />
        </inertial>
    </link>
    <joint name="base_link2base_footprint" type="fixed">
        <parent link="base_footprint" />
        <child link="base_link" />
        <origin rpy="0 0 0" xyz="0 0 0.032" />
    </joint>
    <link name="Link1">
        <inertial>
            <origin rpy="0 0 0" xyz="0.011601 0.022341 0.044136" />
            <mass value="0.001" />
            <inertia ixx="10" ixy="0" ixz="0" iyy="10" iyz="0" izz="10" />
        </inertial>
        <visual>
            <origin rpy="0 0 0" xyz="0 0 0" />
            <geometry>
                <mesh filename="package://robot_description/meshes/Link1.STL" />
            </geometry>
            <material name="">
                <color rgba="0.83 0.83 0.83 1" />
            </material>
        </visual>
        <collision>
            <origin rpy="0 0 0" xyz="0 0 0" />
            <geometry>
                <mesh filename="package://robot_description/meshes/Link1.STL" />
            </geometry>
        </collision>
    </link>
    <joint name="joint1" type="revolute">
        <origin rpy="0 0 0" xyz="0 0 0.065406" />
        <parent link="base_link" />
        <child link="Link1" />
        <axis xyz="0 0 1" />
        <limit effort="200" lower="-1.7453" upper="2.7925" velocity="200" />
    </joint>
    <link name="Link2">
        <inertial>
            <origin rpy="0 0 0" xyz="0.054694 0.0036383 -0.0056108" />
            <mass value="0.001" />
            <inertia ixx="10" ixy="0" ixz="0" iyy="10" iyz="0" izz="10" />
        </inertial>
        <visual>
            <origin rpy="0 0 0" xyz="0 0 0" />
            <geometry>
                <mesh filename="package://robot_description/meshes/Link2.STL" />
            </geometry>
            <material name="">
                <color rgba="1 0.65 0 1" />
            </material>
        </visual>
        <collision>
            <origin rpy="0 0 0" xyz="0 0 0" />
            <geometry>
                <mesh filename="package://robot_description/meshes/Link2.STL" />
            </geometry>
        </collision>
    </link>
    <joint name="joint2" type="revolute">
        <origin rpy="3.1402 -1.5708 1.5722" xyz="0.029687 -0.022 0.061593" />
        <parent link="Link1" />
        <child link="Link2" />
        <axis xyz="0 0 1" />
        <limit effort="200" lower="-0.5235" upper="1.2217" velocity="200" />
    </joint>
    <link name="Link3">
        <inertial>
            <origin rpy="0 0 0" xyz="0.0099997 0.0071403 0.037517" />
            <mass value="0.001" />
            <inertia ixx="10" ixy="0" ixz="0" iyy="10" iyz="0" izz="10" />
        </inertial>
        <visual>
            <origin rpy="0 0 0" xyz="0 0 0" />
            <geometry>
                <mesh filename="package://robot_description/meshes/Link3.STL" />
            </geometry>
            <material name="">
                <color rgba="0.83 0.83 0.83 1" />
            </material>
        </visual>
        <collision>
            <origin rpy="0 0 0" xyz="0 0 0" />
            <geometry>
                <mesh filename="package://robot_description/meshes/Link3.STL" />
            </geometry>
        </collision>
    </link>
    <joint name="joint3" type="revolute">
        <origin rpy="0 0 0" xyz="0.108 0 -0.0094471" />
        <parent link="Link2" />
        <child link="Link3" />
        <axis xyz="0 0 1" />
        <limit effort="200" lower="-2.9671" upper="1.0472" velocity="200" />
    </joint>
    <link name="Link4">
        <inertial>
            <origin rpy="0 0 0" xyz="-8.0804E-06 0.0043797 0.040569" />
            <mass value="0.001" />
            <inertia ixx="10" ixy="0" ixz="0" iyy="10" iyz="0" izz="10" />
        </inertial>
        <visual>
            <origin rpy="0 0 0" xyz="0 0 0" />
            <geometry>
                <mesh filename="package://robot_description/meshes/Link4.STL" />
            </geometry>
            <material name="">
                <color rgba="1 0.65 0 1" />
            </material>
        </visual>
        <collision>
            <origin rpy="0 0 0" xyz="0 0 0" />
            <geometry>
                <mesh filename="package://robot_description/meshes/Link4.STL" />
            </geometry>
        </collision>
    </link>
    <joint name="joint4" type="revolute">
        <origin rpy="-1.5708 0 0" xyz="0.020001 0.10743 0.031439" />
        <parent link="Link3" />
        <child link="Link4" />
        <axis xyz="0 0 1" />
        <limit effort="200" lower="-6.1086" upper="6.1086" velocity="200" />
    </joint>
    <link name="Link5">
        <inertial>
            <origin rpy="0 0 0" xyz="0.00025302 -0.0020133 0.010352" />
            <mass value="0.001" />
            <inertia ixx="10" ixy="0" ixz="0" iyy="10" iyz="0" izz="10" />
        </inertial>
        <visual>
            <origin rpy="0 0 0" xyz="0 0 0" />
            <geometry>
                <mesh filename="package://robot_description/meshes/Link5.STL" />
            </geometry>
            <material name="">
                <color rgba="0.44 0.5 0.56 1" />
            </material>
        </visual>
        <collision>
            <origin rpy="0 0 0" xyz="0 0 0" />
            <geometry>
                <mesh filename="package://robot_description/meshes/Link5.STL" />
            </geometry>
        </collision>
    </link>
    <joint name="joint5" type="revolute">
        <origin rpy="1.5708 -1.5708 -3.1416" xyz="0 -0.010414 0.06155" />
        <parent link="Link4" />
        <child link="Link5" />
        <axis xyz="0 0 -1" />
        <limit effort="200" lower="-3.5779" upper="0.6283" velocity="200" />
    </joint>
    <!-- <link
    name="Link6">
    <inertial>
      <origin
        xyz="5.5511E-17 5.421E-20 -0.010506"
        rpy="0 0 0" />
      <mass
        value="0.001" />
      <inertia
        ixx="10"
        ixy="0"
        ixz="0"
        iyy="10"
        iyz="0"
        izz="10" />
    </inertial>
    <visual>
      <origin
        xyz="0 0 0"
        rpy="0 0 0" />
      <geometry>
        <mesh
          filename="package://robot_description/meshes/Link6.STL" />
      </geometry>
      <material
        name="">
        <color
          rgba="0.83 0.83 0.83 1" />
      </material>
    </visual>
    <collision>
      <origin
        xyz="0 0 0"
        rpy="0 0 0" />
      <geometry>
        <mesh
          filename="package://robot_description/meshes/Link6.STL" />
      </geometry>
    </collision>
  </link>
  <joint
    name="joint6"
    type="revolute">
    <origin
      xyz="0 -0.01628 0.010525"
      rpy="-1.5708 0 0" />
    <parent
      link="Link5" />
    <child
      link="Link6" />
    <axis
      xyz="0 0 1" />
    <limit
      lower="-6.2832"
      upper="6.2832"
      effort="200"
      velocity="200" />
  </joint> -->
    <link name="Link6">
        <inertial>
            <origin rpy="0 0 0" xyz="5.5511E-17 5.421E-20 -0.010506" />
            <mass value="0.001" />
            <inertia ixx="10" ixy="0" ixz="0" iyy="10" iyz="0" izz="10" />
        </inertial>
    </link>
    <joint name="joint6" type="revolute">
        <origin rpy="-1.5708 0 0" xyz="0 -0.01628 0.010525" />
        <parent link="Link5" />
        <child link="Link6" />
        <axis xyz="0 0 1" />
        <limit effort="200" lower="-6.2832" upper="6.2832" velocity="200" />
    </joint>
    <!-- <xacro:include filename="$(find robotiq_2f_140_gripper_visualization)/urdf/robotiq_arg2f_140_model_macro.xacro" />
  <xacro:robotiq_arg2f_140 prefix=""/>
    <parent link="Link5" />
    <origin rpy="0 0 -1.5708" xyz="0 -0.01628 0.010525" />
  </xacro:robotiq_arg2f_140> -->
    <!--
    This is a top-level xacro instantiating the Gazebo-specific version of the
    'robotiq_arg2f_85_gripper' macro (ie: 'robotiq_arg2f_85_gripper_gazebo') and passing it values for all its
    required arguments.

    This file should be considered the Gazebo-specific variant of the file
    with the same name in the robotiq_2f_85_gripper_visualization package. It accepts the same
    arguments, but instead of configuring everything for a real robot, will
    generate a Gazebo-compatible URDF with a ros_control hardware_interface
    attached to it.

    Only use this top-level xacro if you plan on spawning the gripper in Gazebo
    'by itself', without any gripper or any other geometry attached.

    If you need to attach it to a robot and integrate it into a larger workcell and want to spawn that as a single entity in
    Gazebo, DO NOT EDIT THIS FILE.

    Instead: create a new top-level xacro, give it a proper name, include the
    required '.xacro' files, instantiate the models (ie: call the macros) and
    connect everything by adding the appropriate joints.
  -->
    <!--
    Main xacro macro definition of the "Gazebo robot" model.

    This wraps the model of the real robot and adds all elements and parameters
    required by Gazebo.

    It also adds the gazebo_ros_control plugin.

    NOTE: this is NOT a URDF. It cannot directly be loaded by consumers
    expecting a flattened '.urdf' file. See the top-level '.xacro' for that
    (but note: that .xacro must still be processed by the xacro command).

  -->
    <!--
    legal values:
      - hardware_interface/PositionJointInterface
      - hardware_interface/EffortJointInterface

    NOTE: this value must correspond to the controller configured in the
          controller .yaml files in the 'config' directory.
  -->
    <transmission name="finger_joint_trans">
        <type>transmission_interface/SimpleTransmission</type>
        <joint name="finger_joint">
            <hardwareInterface>hardware_interface/EffortJointInterface</hardwareInterface>
        </joint>
        <actuator name="finger_joint_motor">
            <mechanicalReduction>1</mechanicalReduction>
        </actuator>
    </transmission>
    <!-- base link -->
    <link name="base_link_gr">
        <!-- <origin rpy="1.5708 0 0" xyz="0 -0.01628 0.010525" />
      <mass value="0.001" />
      <inertia ixx="10" ixy="0" ixz="0" iyy="10" iyz="0" izz="10" /> -->
    </link>
    <joint name="base_link-robotiq_arg2f_base_link" type="fixed">
        <parent link="base_link_gr" />
        <child link="robotiq_arg2f_base_link" />
        <!-- <origin rpy="1.5708 0 0" xyz="0 -0.01628 0.010525" />
      <limit lower="-6.2832" upper="6.2832" effort="200" velocity="200" /> -->
        <!-- <origin rpy="1.5708 0 0" xyz="0 -0.01628 0.010525" />
      <mass value="0.001" />
      <inertia ixx="10" ixy="0" ixz="0" iyy="10" iyz="0" izz="10" />
      <limit lower="-6.2832" upper="6.2832" effort="200" velocity="200" /> -->
    </joint>
    <link name="robotiq_arg2f_base_link">
        <inertial>
            <origin rpy="0 0 0" xyz="8.625E-08 -4.6583E-06 0.03145" />
            <mass value="0.22652" />
            <inertia ixx="0.00020005" ixy="-4.2442E-10" ixz="-2.9069E-10" iyy="0.00017832" iyz="-3.4402E-08" izz="0.00013478" />
        </inertial>
        <visual>
            <origin rpy="0 0 0" xyz="0 0 0" />
            <geometry>
                <mesh filename="package://robotiq_2f_85_gripper_visualization/meshes/visual/robotiq_arg2f_base_link.stl" />
            </geometry>
            <material name="">
                <color rgba="0.1 0.1 0.1 1" />
            </material>
        </visual>
        <collision>
            <origin rpy="0 0 0" xyz="0 0 0" />
            <geometry>
                <mesh filename="package://robotiq_2f_85_gripper_visualization/meshes/collision/robotiq_arg2f_base_link.stl" />
            </geometry>
        </collision>
    </link>
    <link name="left_outer_knuckle">
        <inertial>
            <origin rpy="0 0 0" xyz="-0.000200000000003065 0.0199435877845359 0.0292245259211331" />
            <mass value="0.00853198276973456" />
            <inertia ixx="2.89328108496468E-06" ixy="-1.57935047237397E-19" ixz="-1.93980378593255E-19" iyy="1.86719750325683E-06" iyz="-1.21858577871576E-06" izz="1.21905238907251E-06" />
        </inertial>
        <visual>
            <origin rpy="0 0 0" xyz="0 0 0" />
            <geometry>
                <mesh filename="package://robotiq_2f_85_gripper_visualization/meshes/visual/robotiq_arg2f_85_outer_knuckle.dae" scale="0.001 0.001 0.001" />
            </geometry>
            <material name="">
                <color rgba="0.792156862745098 0.819607843137255 0.933333333333333 1" />
            </material>
        </visual>
        <collision>
            <origin rpy="0 0 0" xyz="0 0 0" />
            <geometry>
                <mesh filename="package://robotiq_2f_85_gripper_visualization/meshes/collision/robotiq_arg2f_85_outer_knuckle.dae" scale="0.001 0.001 0.001" />
            </geometry>
        </collision>
    </link>
    <link name="left_outer_finger">
        <inertial>
            <origin rpy="0 0 0" xyz="0.00030115855001899 0.0373907951953854 -0.0208027427000385" />
            <mass value="0.022614240507152" />
            <inertia ixx="1.52518312458174E-05" ixy="9.76583423954399E-10" ixz="-5.43838577022588E-10" iyy="6.17694243867776E-06" iyz="6.78636130740228E-06" izz="1.16494917907219E-05" />
        </inertial>
        <visual>
            <origin rpy="0 0 0" xyz="0 0 0" />
            <geometry>
                <mesh filename="package://robotiq_2f_85_gripper_visualization/meshes/visual/robotiq_arg2f_85_outer_finger.dae" scale="0.001 0.001 0.001" />
            </geometry>
            <material name="">
                <color rgba="0.1 0.1 0.1 1" />
            </material>
        </visual>
        <collision>
            <origin rpy="0 0 0" xyz="0 0 0" />
            <geometry>
                <mesh filename="package://robotiq_2f_85_gripper_visualization/meshes/collision/robotiq_arg2f_85_outer_finger.dae" scale="0.001 0.001 0.001" />
            </geometry>
        </collision>
    </link>
    <link name="left_inner_finger">
        <inertial>
            <origin rpy="0 0 0" xyz="0.000299999999999317 0.0160078233491243 -0.0136945669206257" />
            <mass value="0.0104003125914103" />
            <inertia ixx="2.71909453810972E-06" ixy="1.35402465472579E-21" ixz="-7.1817349065269E-22" iyy="7.69100314106116E-07" iyz="6.74715432769696E-07" izz="2.30315190420171E-06" />
        </inertial>
        <visual>
            <origin rpy="0 0 0" xyz="0 0 0" />
            <geometry>
                <mesh filename="package://robotiq_2f_85_gripper_visualization/meshes/visual/robotiq_arg2f_85_inner_finger.dae" scale="0.001 0.001 0.001" />
            </geometry>
            <material name="">
                <color rgba="0.1 0.1 0.1 1" />
            </material>
        </visual>
        <collision>
            <origin rpy="0 0 0" xyz="0 0 0" />
            <geometry>
                <mesh filename="package://robotiq_2f_85_gripper_visualization/meshes/collision/robotiq_arg2f_85_inner_finger.dae" scale="0.001 0.001 0.001" />
            </geometry>
        </collision>
    </link>
    <link name="left_inner_finger_pad">
        <visual>
            <origin rpy="0 0 0" xyz="0 0 0" />
            <geometry>
                <box size="0.022 0.00635 0.0375" />
            </geometry>
            <material name="">
                <color rgba="0.9 0.9 0.9 1" />
            </material>
        </visual>
        <collision>
            <origin rpy="0 0 0" xyz="0 0 0" />
            <geometry>
                <box size="0.022 0.00635 0.0375" />
            </geometry>
            <material name="">
                <color rgba="0.9 0.0 0.0 1" />
            </material>
        </collision>
        <inertial>
            <mass value="0.1" />
            <origin xyz="0 0 0" rpy="0 0 0" />
            <inertia ixx="0.03" iyy="0.03" izz="0.03" ixy="0.0" ixz="0.0" iyz="0.0" />
        </inertial>
    </link>
    <link name="left_inner_knuckle">
        <inertial>
            <origin rpy="0 0 0" xyz="0.000123011831763771 0.0507850843201817 0.00103968640075166" />
            <mass value="0.0271177346495152" />
            <inertia ixx="2.61910379223783E-05" ixy="-2.43616858946494E-07" ixz="-6.37789906117123E-09" iyy="2.8270243746167E-06" iyz="-5.37200748039765E-07" izz="2.83695868220296E-05" />
        </inertial>
        <visual>
            <origin rpy="0 0 0" xyz="0 0 0" />
            <geometry>
                <mesh filename="package://robotiq_2f_85_gripper_visualization/meshes/visual/robotiq_arg2f_85_inner_knuckle.dae" scale="0.001 0.001 0.001" />
            </geometry>
            <material name="">
                <color rgba="0.1 0.1 0.1 1" />
            </material>
        </visual>
        <collision>
            <origin rpy="0 0 0" xyz="0 0 0" />
            <geometry>
                <mesh filename="package://robotiq_2f_85_gripper_visualization/meshes/collision/robotiq_arg2f_85_inner_knuckle.dae" scale="0.001 0.001 0.001" />
            </geometry>
        </collision>
    </link>
    <joint name="left_outer_finger_joint" type="fixed">
        <origin rpy="0 0 0" xyz="0 0.0315 -0.0041" />
        <parent link="left_outer_knuckle" />
        <child link="left_outer_finger" />
        <axis xyz="1 0 0" />
    </joint>
    <joint name="left_inner_knuckle_joint" type="revolute">
        <!-- <origin xyz="0 ${reflect * -0.0127} 0.06142" rpy="${pi / 2 + .725} 0 ${(reflect - 1) * pi / 2}" /> -->
        <origin rpy="0 0 3.141592653589793" xyz="0 -0.0127 0.06142" />
        <parent link="robotiq_arg2f_base_link" />
        <child link="left_inner_knuckle" />
        <axis xyz="1 0 0" />
        <limit effort="1000" lower="0" upper="0.8757" velocity="0.5" />
        <mimic joint="finger_joint" multiplier="1" offset="0" />
    </joint>
    <joint name="left_inner_finger_joint" type="revolute">
        <origin rpy="0 0 0" xyz="0 0.0061 0.0471" />
        <parent link="left_outer_finger" />
        <child link="left_inner_finger" />
        <axis xyz="1 0 0" />
        <limit effort="1000" lower="-0.8757" upper="0" velocity="0.5" />
        <mimic joint="finger_joint" multiplier="-1" offset="0" />
    </joint>
    <joint name="left_inner_finger_pad_joint" type="fixed">
        <origin rpy="0 0 0" xyz="0 -0.0220203446692936 0.03242" />
        <parent link="left_inner_finger" />
        <child link="left_inner_finger_pad" />
        <axis xyz="0 0 1" />
    </joint>
    <joint name="finger_joint" type="revolute">
        <origin rpy="0 0 3.141592653589793" xyz="0 -0.0306011 0.054904" />
        <parent link="robotiq_arg2f_base_link" />
        <child link="left_outer_knuckle" />
        <axis xyz="1 0 0" />
        <limit effort="1000" lower="0" upper="0.8" velocity="0.5" />
    </joint>
    <joint name="right_outer_finger_joint" type="fixed">
        <origin rpy="0 0 0" xyz="0 0.0315 -0.0041" />
        <parent link="right_outer_knuckle" />
        <child link="right_outer_finger" />
        <axis xyz="1 0 0" />
    </joint>
    <joint name="right_inner_knuckle_joint" type="revolute">
        <!-- <origin xyz="0 ${reflect * -0.0127} 0.06142" rpy="${pi / 2 + .725} 0 ${(reflect - 1) * pi / 2}" /> -->
        <origin rpy="0 0 0.0" xyz="0 0.0127 0.06142" />
        <parent link="robotiq_arg2f_base_link" />
        <child link="right_inner_knuckle" />
        <axis xyz="1 0 0" />
        <limit effort="1000" lower="0" upper="0.8757" velocity="0.5" />
        <mimic joint="finger_joint" multiplier="1" offset="0" />
    </joint>
    <joint name="right_inner_finger_joint" type="revolute">
        <origin rpy="0 0 0" xyz="0 0.0061 0.0471" />
        <parent link="right_outer_finger" />
        <child link="right_inner_finger" />
        <axis xyz="1 0 0" />
        <limit effort="1000" lower="-0.8757" upper="0" velocity="0.5" />
        <mimic joint="finger_joint" multiplier="-1" offset="0" />
    </joint>
    <joint name="right_inner_finger_pad_joint" type="fixed">
        <origin rpy="0 0 0" xyz="0 -0.0220203446692936 0.03242" />
        <parent link="right_inner_finger" />
        <child link="right_inner_finger_pad" />
        <axis xyz="0 0 1" />
    </joint>
    <link name="right_outer_knuckle">
        <inertial>
            <origin rpy="0 0 0" xyz="-0.000200000000003065 0.0199435877845359 0.0292245259211331" />
            <mass value="0.00853198276973456" />
            <inertia ixx="2.89328108496468E-06" ixy="-1.57935047237397E-19" ixz="-1.93980378593255E-19" iyy="1.86719750325683E-06" iyz="-1.21858577871576E-06" izz="1.21905238907251E-06" />
        </inertial>
        <visual>
            <origin rpy="0 0 0" xyz="0 0 0" />
            <geometry>
                <mesh filename="package://robotiq_2f_85_gripper_visualization/meshes/visual/robotiq_arg2f_85_outer_knuckle.dae" scale="0.001 0.001 0.001" />
            </geometry>
            <material name="">
                <color rgba="0.792156862745098 0.819607843137255 0.933333333333333 1" />
            </material>
        </visual>
        <collision>
            <origin rpy="0 0 0" xyz="0 0 0" />
            <geometry>
                <mesh filename="package://robotiq_2f_85_gripper_visualization/meshes/collision/robotiq_arg2f_85_outer_knuckle.dae" scale="0.001 0.001 0.001" />
            </geometry>
        </collision>
    </link>
    <link name="right_outer_finger">
        <inertial>
            <origin rpy="0 0 0" xyz="0.00030115855001899 0.0373907951953854 -0.0208027427000385" />
            <mass value="0.022614240507152" />
            <inertia ixx="1.52518312458174E-05" ixy="9.76583423954399E-10" ixz="-5.43838577022588E-10" iyy="6.17694243867776E-06" iyz="6.78636130740228E-06" izz="1.16494917907219E-05" />
        </inertial>
        <visual>
            <origin rpy="0 0 0" xyz="0 0 0" />
            <geometry>
                <mesh filename="package://robotiq_2f_85_gripper_visualization/meshes/visual/robotiq_arg2f_85_outer_finger.dae" scale="0.001 0.001 0.001" />
            </geometry>
            <material name="">
                <color rgba="0.1 0.1 0.1 1" />
            </material>
        </visual>
        <collision>
            <origin rpy="0 0 0" xyz="0 0 0" />
            <geometry>
                <mesh filename="package://robotiq_2f_85_gripper_visualization/meshes/collision/robotiq_arg2f_85_outer_finger.dae" scale="0.001 0.001 0.001" />
            </geometry>
        </collision>
    </link>
    <link name="right_inner_finger">
        <inertial>
            <origin rpy="0 0 0" xyz="0.000299999999999317 0.0160078233491243 -0.0136945669206257" />
            <mass value="0.0104003125914103" />
            <inertia ixx="2.71909453810972E-06" ixy="1.35402465472579E-21" ixz="-7.1817349065269E-22" iyy="7.69100314106116E-07" iyz="6.74715432769696E-07" izz="2.30315190420171E-06" />
        </inertial>
        <visual>
            <origin rpy="0 0 0" xyz="0 0 0" />
            <geometry>
                <mesh filename="package://robotiq_2f_85_gripper_visualization/meshes/visual/robotiq_arg2f_85_inner_finger.dae" scale="0.001 0.001 0.001" />
            </geometry>
            <material name="">
                <color rgba="0.1 0.1 0.1 1" />
            </material>
        </visual>
        <collision>
            <origin rpy="0 0 0" xyz="0 0 0" />
            <geometry>
                <mesh filename="package://robotiq_2f_85_gripper_visualization/meshes/collision/robotiq_arg2f_85_inner_finger.dae" scale="0.001 0.001 0.001" />
            </geometry>
        </collision>
    </link>
    <link name="right_inner_finger_pad">
        <visual>
            <origin rpy="0 0 0" xyz="0 0 0" />
            <geometry>
                <box size="0.022 0.00635 0.0375" />
            </geometry>
            <material name="">
                <color rgba="0.9 0.9 0.9 1" />
            </material>
        </visual>
        <collision>
            <origin rpy="0 0 0" xyz="0 0 0" />
            <geometry>
                <box size="0.022 0.00635 0.0375" />
            </geometry>
            <material name="">
                <color rgba="0.9 0.0 0.0 1" />
            </material>
        </collision>
        <inertial>
            <mass value="0.1" />
            <origin xyz="0 0 0" rpy="0 0 0" />
            <inertia ixx="0.03" iyy="0.03" izz="0.03" ixy="0.0" ixz="0.0" iyz="0.0" />
        </inertial>
    </link>
    <link name="right_inner_knuckle">
        <inertial>
            <origin rpy="0 0 0" xyz="0.000123011831763771 0.0507850843201817 0.00103968640075166" />
            <mass value="0.0271177346495152" />
            <inertia ixx="2.61910379223783E-05" ixy="-2.43616858946494E-07" ixz="-6.37789906117123E-09" iyy="2.8270243746167E-06" iyz="-5.37200748039765E-07" izz="2.83695868220296E-05" />
        </inertial>
        <visual>
            <origin rpy="0 0 0" xyz="0 0 0" />
            <geometry>
                <mesh filename="package://robotiq_2f_85_gripper_visualization/meshes/visual/robotiq_arg2f_85_inner_knuckle.dae" scale="0.001 0.001 0.001" />
            </geometry>
            <material name="">
                <color rgba="0.1 0.1 0.1 1" />
            </material>
        </visual>
        <collision>
            <origin rpy="0 0 0" xyz="0 0 0" />
            <geometry>
                <mesh filename="package://robotiq_2f_85_gripper_visualization/meshes/collision/robotiq_arg2f_85_inner_knuckle.dae" scale="0.001 0.001 0.001" />
            </geometry>
        </collision>
    </link>
    <joint name="right_finger_joint" type="revolute">
        <origin rpy="0 0 0" xyz="0 0.0306011 0.054904" />
        <parent link="robotiq_arg2f_base_link" />
        <child link="right_outer_knuckle" />
        <axis xyz="1 0 0" />
        <limit effort="1000" lower="0" upper="0.81" velocity="0.5" />
        <mimic joint="finger_joint" multiplier="1" offset="0" />
    </joint>
    <!-- Mimic joints plugin-->
    <gazebo>
        <plugin filename="libroboticsgroup_upatras_gazebo_mimic_joint_plugin.so" name="mimic_robotiq_85_1">
            <joint>finger_joint</joint>
            <mimicJoint>left_inner_knuckle_joint</mimicJoint>
            <multiplier>1.0</multiplier>
        </plugin>
        <plugin filename="libroboticsgroup_upatras_gazebo_mimic_joint_plugin.so" name="mimic_robotiq_85_2">
            <joint>finger_joint</joint>
            <mimicJoint>left_inner_finger_joint</mimicJoint>
            <multiplier>-1.0</multiplier>
        </plugin>
        <plugin filename="libroboticsgroup_upatras_gazebo_mimic_joint_plugin.so" name="mimic_robotiq_85_3">
            <joint>finger_joint</joint>
            <mimicJoint>right_inner_knuckle_joint</mimicJoint>
            <multiplier>1.0</multiplier>
        </plugin>
        <plugin filename="libroboticsgroup_upatras_gazebo_mimic_joint_plugin.so" name="mimic_robotiq_85_4">
            <joint>finger_joint</joint>
            <mimicJoint>right_inner_finger_joint</mimicJoint>
            <multiplier>-1.0</multiplier>
        </plugin>
        <plugin filename="libroboticsgroup_upatras_gazebo_mimic_joint_plugin.so" name="mimic_robotiq_85_5">
            <joint>finger_joint</joint>
            <mimicJoint>right_finger_joint</mimicJoint>
            <multiplier>1.0</multiplier>
        </plugin>
        <plugin name="gazebo_ros_control">
            <robotNamespace>/</robotNamespace>
        </plugin>
    </gazebo>
    <!-- Links colors  -->
    <gazebo reference="robotiq_arg2f_base_link">
        <material>Gazebo/Black</material>
    </gazebo>
    <gazebo reference="left_outer_knuckle">
        <material>Gazebo/Grey</material>
    </gazebo>
    <gazebo reference="left_outer_finger">
        <material>Gazebo/Black</material>
    </gazebo>
    <gazebo reference="left_inner_finger">
        <material>Gazebo/Grey</material>
    </gazebo>
    <gazebo reference="left_inner_knuckle">
        <material>Gazebo/Black</material>
    </gazebo>
    <gazebo reference="right_outer_knuckle">
        <material>Gazebo/Grey</material>
    </gazebo>
    <gazebo reference="right_outer_finger">
        <material>Gazebo/Black</material>
    </gazebo>
    <gazebo reference="right_inner_finger">
        <material>Gazebo/Grey</material>
    </gazebo>
    <gazebo reference="right_inner_knuckle">
        <material>Gazebo/Black</material>
    </gazebo>
    <!--
      Inject Gazebo ROS Control plugin, which allows us to use ros_control
      controllers to control the virtual robot hw.
    -->
    <gazebo>
        <plugin filename="libgazebo_ros_control.so" name="ros_control" />
    </gazebo>
    <!--
    Attach the Gazebo model to Gazebo's world frame.
  -->
    <!-- <link name="world"/>
  <joint name="world_joint" type="fixed">
    <parent link="world"/>
    <child link="base_link"/>
    <origin xyz="0 0 0" rpy="0 0 0"/>
  </joint> -->
    <joint name="ft_gripper_joint" type="fixed">
        <parent link="Link6" />
        <child link="base_link_gr" />
        <origin rpy="3.14 0 0" xyz="5.5511E-17 5.421E-20 -0.01" />
        <!-- <mass value="0.001" /> -->
        <!-- <inertia ixx="10" ixy="0" ixz="0" iyy="10" iyz="0" izz="10" /> -->
    </joint>
    <!-- <xacro:include filename="$(find robotiq_2f_85_gripper_gazebo)/urdf/robotiq_arg2f_85.xacro" />
  <joint name="joint6" type="revolute">
      <parent link="Link5"/>
      <child link="base_link_gr"/>
      <origin rpy="1.5708 0 0" xyz="0 -0.01628 0.010525" />
      <limit lower="-6.2832" upper="6.2832" effort="200" velocity="200" />
      <mass value="0.001" />
      <inertia ixx="10" ixy="0" ixz="0" iyy="10" iyz="0" izz="10" />
  </joint> -->
    <!--   
  <xacro:include filename="$(find ur10_rg2_ros)/robot_descriptions/description/rg2.urdf.xacro"/> 
  <xacro:rg2 parent_link="Link5" parent_joint="joint5" name="rg2" />
  <xacro:rg2_eef parent_link="rg2_body_link" parent_joint="rg2_joint" name="rg2_eef" />
  <xacro:rg2_gripper parent_link="rg2_eef_link" parent_joint="rg2_eef_joint" name="rg2_gripper" />
  <xacro:rg2_gripper_finger_left parent_link="rg2_gripper_left_finger_link" parent_joint="rg2_gripper_left_finger_joint" name="rg2_gripper_finger_left" />
  <xacro:rg2_gripper_finger_right parent_link="rg2_gripper_right_finger_link" parent_joint="rg2_gripper_right_finger_joint" name="rg2_gripper_finger_right" /> -->
    <!-- <joint name="base_link_gr2world" type="fixed">
    <parent link="base_link_gr"/>
    <child link="world"/>
  </joint> -->
    <link name="world" />
    <joint name="fixed" type="fixed">
        <origin rpy="0.000002 0 0.000050" xyz="-0.182938 -0.095742 1.014999" />
        <parent link="world" />
        <child link="base_footprint" />
    </joint>
    <!-- T265 Fisheye:

  gazebo_ros_camera supports only plumb_bob
  D: [-0.007419134024530649, 0.041209351271390915, -0.03811917081475258, 0.006366158835589886, 0.0]

  <distortionK1>-0.007419134024530649</distortionK1>
  <distortionK2>0.041209351271390915</distortionK2>
  <distortionK3>-0.03811917081475258</distortionK3>
  <distortionT1>0.006366158835589886</distortionT1>
  <distortionT2>0.0</distortionT2>

       [fx'  0  cx' Tx]
   P = [ 0  fy' cy' Ty]
       [ 0   0   1   0]

   P : [ 285.5480041503906, 0.0, 416.00531005859375, 0.0,
         0.0, 285.3793029785156, 403.38909912109375, 0.0,
         0.0, 0.0, 1.0, 0.0 ]

  <CxPrime>416.00531005859375</CxPrime>

       [fx  0 cx]
   K = [ 0 fy cy]
       [ 0  0  1]

   K : [ 285.5480041503906, 0.0, 416.00531005859375,
         0.0, 285.3793029785156, 403.38909912109375,
         0.0, 0.0, 1.0]

  <Cx>16.00531005859375</Cx>
  <Cy>403.38909912109375</Cy>

  -->
    <!-- INTEL REALSENSE T265 -->
    <!-- INTEL REALSENSE D435 -->
    <!-- INTEL REALSENSE R200 -->
    <!-- camera body, with origin at bottom screw mount -->
    <joint name="d435_joint" type="fixed">
        <origin rpy="1.5707963267948966 1.5707963267948966 1.5707963267948966" xyz="0.3 0 0.5" />
        <parent link="base_link" />
        <child link="d435_bottom_screw_frame" />
    </joint>
    <link name="d435_bottom_screw_frame" />
    <joint name="d435_link_joint" type="fixed">
        <origin rpy="0 0 0" xyz="0 0.0175 0.0125" />
        <parent link="d435_bottom_screw_frame" />
        <child link="d435_link" />
    </joint>
    <link name="d435_link">
        <visual>
            <origin rpy="1.5707963267948966 0 1.5707963267948966" xyz="0.0149 -0.0175 0" />
            <geometry>
                <mesh filename="package://realsense_ros_gazebo/meshes/realsense_d435.stl" />
            </geometry>
            <material name="white">
                <color rgba="1 1 1 1" />
            </material>
        </visual>
        <collision>
            <origin rpy="0 0 0" xyz="0 -0.0175 0" />
            <geometry>
                <box size="0.02505 0.09 0.025" />
            </geometry>
        </collision>
        <inertial>
            <mass value="0.564" />
            <origin rpy="0 0 0" xyz="0 -0.0175 0" />
            <inertia ixx="0.000410075" ixy="0" ixz="0" iyy="5.8867617499999996e-05" iyz="0" izz="5.8867617499999996e-05" />
        </inertial>
    </link>
    <!-- camera depth joints and links -->
    <joint name="d435_depth_joint" type="fixed">
        <origin rpy="0 0 0" xyz="0 0 0" />
        <parent link="d435_link" />
        <child link="d435_depth_frame" />
    </joint>
    <link name="d435_depth_frame" />
    <joint name="d435_depth_optical_joint" type="fixed">
        <origin rpy="-1.5707963267948966 0 -1.5707963267948966" xyz="0 0 0" />
        <parent link="d435_depth_frame" />
        <child link="d435_depth_optical_frame" />
    </joint>
    <link name="d435_depth_optical_frame" />
    <!-- camera left IR joints and links -->
    <joint name="d435_left_ir_joint" type="fixed">
        <origin rpy="0 0 0" xyz="0 0.0 0" />
        <parent link="d435_depth_frame" />
        <child link="d435_left_ir_frame" />
    </joint>
    <link name="d435_left_ir_frame" />
    <joint name="d435_left_ir_optical_joint" type="fixed">
        <origin rpy="-1.5707963267948966 0 -1.5707963267948966" xyz="0 0 0" />
        <parent link="d435_left_ir_frame" />
        <child link="d435_left_ir_optical_frame" />
    </joint>
    <link name="d435_left_ir_optical_frame" />
    <!-- camera right IR joints and links -->
    <joint name="d435_right_ir_joint" type="fixed">
        <origin rpy="0 0 0" xyz="0 -0.05 0" />
        <parent link="d435_depth_frame" />
        <child link="d435_right_ir_frame" />
    </joint>
    <link name="d435_right_ir_frame" />
    <joint name="d435_right_ir_optical_joint" type="fixed">
        <origin rpy="-1.5707963267948966 0 -1.5707963267948966" xyz="0 0 0" />
        <parent link="d435_right_ir_frame" />
        <child link="d435_right_ir_optical_frame" />
    </joint>
    <link name="d435_right_ir_optical_frame" />
    <!-- camera color joints and links -->
    <joint name="d435_color_joint" type="fixed">
        <origin rpy="0 0 0" xyz="0 0.015 0" />
        <parent link="d435_depth_frame" />
        <child link="d435_color_frame" />
    </joint>
    <link name="d435_color_frame" />
    <joint name="d435_color_optical_joint" type="fixed">
        <origin rpy="-1.5707963267948966 0 -1.5707963267948966" xyz="0 0 0" />
        <parent link="d435_color_frame" />
        <child link="d435_color_optical_frame" />
    </joint>
    <link name="d435_color_optical_frame" />
    <!-- gazebo plugin -->
    <gazebo reference="d435_link">
        <self_collide>0</self_collide>
        <enable_wind>0</enable_wind>
        <kinematic>0</kinematic>
        <gravity>1</gravity>
        <mu2>1</mu2>
        <fdir1>0 0 0</fdir1>
        <kp>1e+13</kp>
        <kd>1</kd>
        <sensor name="d435_color" type="camera">
            <camera name="d435">
                <horizontal_fov>1.4870205226991688</horizontal_fov>
                <image>
                    <width>1920</width>
                    <height>1080</height>
                    <format>RGB_INT8</format>
                </image>
                <clip>
                    <near>0.1</near>
                    <far>100</far>
                </clip>
                <noise>
                    <type>gaussian</type>
                    <mean>0.0</mean>
                    <stddev>0.007</stddev>
                </noise>
            </camera>
            <always_on>1</always_on>
            <update_rate>30</update_rate>
            <visualize>1</visualize>
        </sensor>
        <sensor name="d435_ired1" type="camera">
            <camera name="d435">
                <horizontal_fov>1.4870205226991688</horizontal_fov>
                <image>
                    <width>640</width>
                    <height>480</height>
                    <format>L_INT8</format>
                </image>
                <clip>
                    <near>0.1</near>
                    <far>100</far>
                </clip>
                <noise>
                    <type>gaussian</type>
                    <mean>0.0</mean>
                    <stddev>0.05</stddev>
                </noise>
            </camera>
            <always_on>1</always_on>
            <update_rate>90</update_rate>
            <visualize>0</visualize>
        </sensor>
        <sensor name="d435_ired2" type="camera">
            <camera name="d435">
                <horizontal_fov>1.4870205226991688</horizontal_fov>
                <image>
                    <width>640</width>
                    <height>480</height>
                    <format>L_INT8</format>
                </image>
                <clip>
                    <near>0.1</near>
                    <far>100</far>
                </clip>
                <noise>
                    <type>gaussian</type>
                    <mean>0.0</mean>
                    <stddev>0.05</stddev>
                </noise>
            </camera>
            <always_on>1</always_on>
            <update_rate>90</update_rate>
            <visualize>0</visualize>
        </sensor>
        <sensor name="d435_depth" type="depth">
            <camera name="d435">
                <horizontal_fov>1.4870205226991688</horizontal_fov>
                <image>
                    <width>1920</width>
                    <height>1080</height>
                </image>
                <clip>
                    <near>0.1</near>
                    <far>100</far>
                </clip>
                <noise>
                    <type>gaussian</type>
                    <mean>0.0</mean>
                    <stddev>0.100</stddev>
                </noise>
            </camera>
            <always_on>1</always_on>
            <update_rate>90</update_rate>
            <visualize>0</visualize>
        </sensor>
    </gazebo>
    <gazebo>
        <plugin filename="librealsense_gazebo_plugin.so" name="d435">
            <prefix>d435_</prefix>
            <depthUpdateRate>20</depthUpdateRate>
            <colorUpdateRate>20</colorUpdateRate>
            <infraredUpdateRate>20</infraredUpdateRate>
            <depthTopicName>depth/image_raw</depthTopicName>
            <depthCameraInfoTopicName>depth/camera_info</depthCameraInfoTopicName>
            <colorTopicName>color/image_raw</colorTopicName>
            <colorCameraInfoTopicName>color/camera_info</colorCameraInfoTopicName>
            <infrared1TopicName>infra1/image_raw</infrared1TopicName>
            <infrared1CameraInfoTopicName>infra1/camera_info</infrared1CameraInfoTopicName>
            <infrared2TopicName>infra2/image_raw</infrared2TopicName>
            <infrared2CameraInfoTopicName>infra2/camera_info</infrared2CameraInfoTopicName>
            <colorOpticalframeName>d435_color_optical_frame</colorOpticalframeName>
            <depthOpticalframeName>d435_depth_optical_frame</depthOpticalframeName>
            <infrared1OpticalframeName>d435_infrared1_optical_frame</infrared1OpticalframeName>
            <infrared2OpticalframeName>d435_infrared2_optical_frame</infrared2OpticalframeName>
            <rangeMinDepth>0.1</rangeMinDepth>
            <rangeMaxDepth>10.0</rangeMaxDepth>
            <pointCloud>true</pointCloud>
            <pointCloudTopicName>points</pointCloudTopicName>
            <pointCloudCutoff>0.1</pointCloudCutoff>
            <pointCloudCutoffMax>9.0</pointCloudCutoffMax>
        </plugin>
    </gazebo>
    <!-- <xacro:mirobot prefix="" transmission_hw_interface="hardware_interface/PositionJointInterface"/> -->
    <transmission name="tran1">
        <type>transmission_interface/SimpleTransmission</type>
        <joint name="joint1">
            <hardwareInterface>hardware_interface/PositionJointInterface</hardwareInterface>
        </joint>
        <actuator name="motor1">
            <hardwareInterface>hardware_interface/PositionJointInterface</hardwareInterface>
            <mechanicalReduction>1</mechanicalReduction>
        </actuator>
    </transmission>
    <transmission name="tran1">
        <type>transmission_interface/SimpleTransmission</type>
        <joint name="joint2">
            <hardwareInterface>hardware_interface/PositionJointInterface</hardwareInterface>
        </joint>
        <actuator name="motor1">
            <hardwareInterface>hardware_interface/PositionJointInterface</hardwareInterface>
            <mechanicalReduction>1</mechanicalReduction>
        </actuator>
    </transmission>
    <transmission name="tran1">
        <type>transmission_interface/SimpleTransmission</type>
        <joint name="joint3">
            <hardwareInterface>hardware_interface/PositionJointInterface</hardwareInterface>
        </joint>
        <actuator name="motor1">
            <hardwareInterface>hardware_interface/PositionJointInterface</hardwareInterface>
            <mechanicalReduction>1</mechanicalReduction>
        </actuator>
    </transmission>
    <transmission name="tran1">
        <type>transmission_interface/SimpleTransmission</type>
        <joint name="joint4">
            <hardwareInterface>hardware_interface/PositionJointInterface</hardwareInterface>
        </joint>
        <actuator name="motor1">
            <hardwareInterface>hardware_interface/PositionJointInterface</hardwareInterface>
            <mechanicalReduction>1</mechanicalReduction>
        </actuator>
    </transmission>
    <transmission name="tran1">
        <type>transmission_interface/SimpleTransmission</type>
        <joint name="joint5">
            <hardwareInterface>hardware_interface/PositionJointInterface</hardwareInterface>
        </joint>
        <actuator name="motor1">
            <hardwareInterface>hardware_interface/PositionJointInterface</hardwareInterface>
            <mechanicalReduction>1</mechanicalReduction>
        </actuator>
    </transmission>
    <transmission name="tran1">
        <type>transmission_interface/SimpleTransmission</type>
        <joint name="joint6">
            <hardwareInterface>hardware_interface/PositionJointInterface</hardwareInterface>
        </joint>
        <actuator name="motor1">
            <hardwareInterface>hardware_interface/PositionJointInterface</hardwareInterface>
            <mechanicalReduction>1</mechanicalReduction>
        </actuator>
    </transmission>
    <transmission name="tran1">
        <type>transmission_interface/SimpleTransmission</type>
        <joint name="finger_joint">
            <hardwareInterface>hardware_interface/PositionJointInterface</hardwareInterface>
        </joint>
        <actuator name="motor1">
            <hardwareInterface>hardware_interface/PositionJointInterface</hardwareInterface>
            <mechanicalReduction>1</mechanicalReduction>
        </actuator>
    </transmission>
    <!-- <xacro:transmission_block joint_name="base_link_gr"/>
  <xacro:transmission_block joint_name="robotiq_arg2f_base_link"/>
  <xacro:transmission_block joint_name="left_outer_knuckle"/>
  <xacro:transmission_block joint_name="left_inner_finger"/>
  <xacro:transmission_block joint_name="left_inner_finger_pad"/>
  <xacro:transmission_block joint_name="left_inner_knuckle"/>
  <xacro:transmission_block joint_name="right_outer_knuckle"/>
  <xacro:transmission_block joint_name="right_outer_finger"/>
  <xacro:transmission_block joint_name="right_inner_finger"/>
  <xacro:transmission_block joint_name="right_inner_finger_pad"/>
  <xacro:transmission_block joint_name="right_inner_knuckle"/> -->
    <!-- <xacro:transmission_block joint_name="joint6"/> -->
    <!-- ros_control plugin -->
    <gazebo>
        <plugin filename="libgazebo_ros_control.so" name="gazebo_ros_control">
            <robotNamespace>/mirobot</robotNamespace>
            <robotSimType>gazebo_ros_control/DefaultRobotHWSim</robotSimType>
            <legacyModeNS>true</legacyModeNS>
        </plugin>
    </gazebo>
    <!-- vacuum_gripper plugin -->
    <!-- <gazebo>
    <plugin name="gazebo_ros_vacuum_gripper" filename="libvacuum_plugin.so">
      <robotNamespace>/mirobot/vacuum_gripper</robotNamespace>
      <bodyName>link_6</bodyName>
      <topicName>grasping</topicName>
      <maxDistance>0.05</maxDistance>
      <minDistance>0.03</minDistance>
    </plugin>
</gazebo> -->
    <!-- gazebo grasp-fix-->
    <gazebo>
        <plugin filename="libgazebo_grasp_fix.so" name="gazebo_grasp_fix">
            <arm>
                <arm_name>robotiq_gr_fix</arm_name>
                <palm_link>Link6</palm_link>
                <!-- <gripper_link>base_link_gr</gripper_link>
            <gripper_link>robotiq_arg2f_base_link</gripper_link>
            <gripper_link>left_outer_finger</gripper_link>
            <gripper_link>left_inner_finger_pad</gripper_link>
            <gripper_link>right_outer_finger</gripper_link>
            <gripper_link>right_inner_finger_pad</gripper_link> -->
                <gripper_link>left_outer_knuckle</gripper_link>
                <gripper_link>left_inner_finger</gripper_link>
                <gripper_link>left_inner_knuckle</gripper_link>
                <gripper_link>right_outer_knuckle</gripper_link>
                <gripper_link>right_inner_finger</gripper_link>
                <gripper_link>right_inner_knuckle</gripper_link>
            </arm>
            <forces_angle_tolerance>150</forces_angle_tolerance>
            <update_rate>130</update_rate>
            <grip_count_threshold>2</grip_count_threshold>
            <max_grip_count>8</max_grip_count>
            <release_tolerance>0.01</release_tolerance>
            <disable_collisions_on_attach>true</disable_collisions_on_attach>
            <contact_topic>__default_topic__</contact_topic>
        </plugin>
    </gazebo>
    <!-- <gazebo reference="link_6"> -->
    <!-- <gazebo reference="left_inner_finger_pad">
  <selfCollide>true</selfCollide>
  <mu1>50</mu1>
  <mu2>50</mu2>
  <minDepth>0.003</minDepth>
  <maxVel>0</maxVel>
  <kp>1000000.0</kp>
  <kd>1.0</kd>
  <material>Gazebo/Grey</material>
  </gazebo>

  <gazebo reference="right_inner_finger_pad">
  <selfCollide>true</selfCollide>
  <mu1>50</mu1>
  <mu2>50</mu2>
  <minDepth>0.003</minDepth>
  <maxVel>0</maxVel>
  <kp>1000000.0</kp>
  <kd>1.0</kd>
  <material>Gazebo/Grey</material>
  </gazebo> -->
    <transmission name="trans_left_inner_knuckle_joint">
        <type>transmission_interface/SimpleTransmission</type>
        <joint name="left_inner_knuckle_joint">
            <hardwareInterface>hardware_interface/EffortJointInterface</hardwareInterface>
        </joint>
        <actuator name="left_inner_knuckle_joint_motor">
            <hardwareInterface>hardware_interface/EffortJointInterface</hardwareInterface>
            <mechanicalReduction>1</mechanicalReduction>
        </actuator>
    </transmission>
    <transmission name="trans_left_inner_finger_joint">
        <type>transmission_interface/SimpleTransmission</type>
        <joint name="left_inner_finger_joint">
            <hardwareInterface>hardware_interface/EffortJointInterface</hardwareInterface>
        </joint>
        <actuator name="left_inner_finger_joint_motor">
            <hardwareInterface>hardware_interface/EffortJointInterface</hardwareInterface>
            <mechanicalReduction>1</mechanicalReduction>
        </actuator>
    </transmission>
    <transmission name="trans_right_inner_knuckle_joint">
        <type>transmission_interface/SimpleTransmission</type>
        <joint name="right_inner_knuckle_joint">
            <hardwareInterface>hardware_interface/EffortJointInterface</hardwareInterface>
        </joint>
        <actuator name="right_inner_knuckle_joint_motor">
            <hardwareInterface>hardware_interface/EffortJointInterface</hardwareInterface>
            <mechanicalReduction>1</mechanicalReduction>
        </actuator>
    </transmission>
    <transmission name="trans_right_inner_finger_joint">
        <type>transmission_interface/SimpleTransmission</type>
        <joint name="right_inner_finger_joint">
            <hardwareInterface>hardware_interface/EffortJointInterface</hardwareInterface>
        </joint>
        <actuator name="right_inner_finger_joint_motor">
            <hardwareInterface>hardware_interface/EffortJointInterface</hardwareInterface>
            <mechanicalReduction>1</mechanicalReduction>
        </actuator>
    </transmission>
    <transmission name="trans_right_finger_joint">
        <type>transmission_interface/SimpleTransmission</type>
        <joint name="right_finger_joint">
            <hardwareInterface>hardware_interface/EffortJointInterface</hardwareInterface>
        </joint>
        <actuator name="right_finger_joint_motor">
            <hardwareInterface>hardware_interface/EffortJointInterface</hardwareInterface>
            <mechanicalReduction>1</mechanicalReduction>
        </actuator>
    </transmission>
</robot>

